[32m2022-12-02 16:33:21 -0500[0m - dagster - [34mDEBUG[0m - matriz_data - baf78662-fc2d-40fb-ad4e-9a1f155bea4b - 36646 - LOGS_CAPTURED - Started capturing logs in process (pid: 36646).
[32m2022-12-02 16:33:21 -0500[0m - dagster - [34mDEBUG[0m - matriz_data - baf78662-fc2d-40fb-ad4e-9a1f155bea4b - 36646 - load_table - STEP_START - Started execution of step "load_table".
[32m2022-12-02 16:33:23 -0500[0m - dagster - [34mERROR[0m - [31mmatriz_data - baf78662-fc2d-40fb-ad4e-9a1f155bea4b - 36646 - load_table - STEP_FAILURE - Execution of step "load_table" failed.

dagster._core.errors.DagsterExecutionStepExecutionError: Error occurred while executing op "load_table"::

FileNotFoundError: [Errno 2] No such file or directory: './data/Matriz_adyacencia.xlsx'

Stack Trace:
  File "/Users/fabio/miniforge3/envs/dagsterETL/lib/python3.9/site-packages/dagster/_core/execution/plan/utils.py", line 47, in solid_execution_error_boundary
    yield
  File "/Users/fabio/miniforge3/envs/dagsterETL/lib/python3.9/site-packages/dagster/_utils/__init__.py", line 447, in iterate_with_context
    next_output = next(iterator)
  File "/Users/fabio/miniforge3/envs/dagsterETL/lib/python3.9/site-packages/dagster/_core/execution/plan/compute_generator.py", line 74, in _coerce_solid_compute_fn_to_iterator
    result = fn(context, **kwargs) if context_arg_provided else fn(**kwargs)
  File "/Users/fabio/Documents/dagster_home/etldagster/etldagster/ops/etl.py", line 14, in load_table
    df = pd.read_excel('./data/Matriz_adyacencia.xlsx', engine='openpyxl', skiprows=1, index_col=0)
  File "/Users/fabio/miniforge3/envs/dagsterETL/lib/python3.9/site-packages/pandas/util/_decorators.py", line 211, in wrapper
    return func(*args, **kwargs)
  File "/Users/fabio/miniforge3/envs/dagsterETL/lib/python3.9/site-packages/pandas/util/_decorators.py", line 331, in wrapper
    return func(*args, **kwargs)
  File "/Users/fabio/miniforge3/envs/dagsterETL/lib/python3.9/site-packages/pandas/io/excel/_base.py", line 482, in read_excel
    io = ExcelFile(io, storage_options=storage_options, engine=engine)
  File "/Users/fabio/miniforge3/envs/dagsterETL/lib/python3.9/site-packages/pandas/io/excel/_base.py", line 1695, in __init__
    self._reader = self._engines[engine](self._io, storage_options=storage_options)
  File "/Users/fabio/miniforge3/envs/dagsterETL/lib/python3.9/site-packages/pandas/io/excel/_openpyxl.py", line 557, in __init__
    super().__init__(filepath_or_buffer, storage_options=storage_options)
  File "/Users/fabio/miniforge3/envs/dagsterETL/lib/python3.9/site-packages/pandas/io/excel/_base.py", line 535, in __init__
    self.handles = get_handle(
  File "/Users/fabio/miniforge3/envs/dagsterETL/lib/python3.9/site-packages/pandas/io/common.py", line 865, in get_handle
    handle = open(handle, ioargs.mode)
[0m
